samples.csv
SELL ADD 7891 110
printorderbook 48
BUY ADD 7903 18
printorderbook 38
SELL ADD 7812 344
printorderbook 65
BUY ADD 7930 351
printorderbook 54
SELL ADD 7865 378
printorderbook 26
BUY ADD 7950 37
printorderbook 62
SELL ADD 7895 138
BUY CANCEL 2 18
printorderbook 63
SELL ADD 7900 160
printorderbook 35
SELL ADD 7814 193
printorderbook 64
SELL ADD 7809 385
printorderbook 10
BUY ADD 7925 363
printorderbook 62
SELL ADD 7902 423
printorderbook 59
SELL ADD 7893 90
printorderbook 40
SELL ADD 7899 374
SELL CANCEL 13 90
printorderbook 59
SELL ADD 7825 138
printorderbook 30
BUY ADD 7847 159
printorderbook 46
BUY ADD 7877 75
printorderbook 59
BUY ADD 7829 205
printorderbook 40
SELL ADD 7991 101
printorderbook 44
BUY ADD 7960 239
printorderbook 15
BUY ADD 7827 206
SELL CANCEL 19 101
printorderbook 12
SELL ADD 7826 228
printorderbook 32
BUY ADD 7842 455
printorderbook 60
BUY ADD 7963 232
printorderbook 45
BUY ADD 7939 477
printorderbook 21
BUY ADD 7882 438
printorderbook 51
BUY ADD 7940 11
printorderbook 37
SELL ADD 7897 341
BUY CANCEL 26 438
printorderbook 62
SELL ADD 7997 224
printorderbook 37
SELL ADD 7960 107
printorderbook 12
BUY ADD 7799 364
printorderbook 30
BUY ADD 7966 415
printorderbook 7
BUY ADD 7842 195
printorderbook 66
SELL ADD 7856 392
printorderbook 20
SELL ADD 7996 410
SELL CANCEL 15 138
printorderbook 13
SELL ADD 7850 52
printorderbook 45
BUY ADD 7950 317
printorderbook 42
SELL ADD 7822 264
printorderbook 42
BUY ADD 7831 430
printorderbook 39
SELL ADD 7905 294
printorderbook 31
SELL ADD 7888 195
printorderbook 6
SELL ADD 7934 365
SELL CANCEL 40 294
printorderbook 66
SELL ADD 7931 303
printorderbook 11
SELL ADD 7904 8
printorderbook 45
BUY ADD 7993 422
printorderbook 32
SELL ADD 7940 219
printorderbook 53
BUY ADD 7950 3
printorderbook 7
BUY ADD 7948 4
printorderbook 37
BUY ADD 7842 314
SELL CANCEL 35 410
printorderbook 20
SELL ADD 7861 53
printorderbook 55
SELL ADD 7831 149
printorderbook 34
BUY ADD 7829 417
printorderbook 41
SELL ADD 7996 2
printorderbook 3
SELL ADD 7947 269
printorderbook 9
SELL ADD 7922 64
printorderbook 67
BUY ADD 7851 213
SELL CANCEL 50 53
printorderbook 53
SELL ADD 7932 106
printorderbook 39
SELL ADD 7885 344
printorderbook 59
BUY ADD 7815 385
printorderbook 18
BUY ADD 7949 341
printorderbook 4
SELL ADD 7930 186
printorderbook 17
SELL ADD 7831 331
printorderbook 66
BUY ADD 7803 361
BUY CANCEL 4 351
printorderbook 37
SELL ADD 7994 165
printorderbook 52
SELL ADD 7987 128
printorderbook 10
SELL ADD 7820 185
printorderbook 24
BUY ADD 7951 350
printorderbook 66
SELL ADD 7890 121
printorderbook 30
SELL ADD 7842 264
printorderbook 61
BUY ADD 7876 230
BUY CANCEL 56 213
printorderbook 1
BUY ADD 7836 68
printorderbook 66
BUY ADD 7868 255
printorderbook 59
SELL ADD 7925 22
printorderbook 54
BUY ADD 7843 45
printorderbook 50
SELL ADD 7875 117
printorderbook 33
BUY ADD 7806 17
printorderbook 42
SELL ADD 7906 202
BUY CANCEL 74 45
printorderbook 61
SELL ADD 7927 466
printorderbook 57
BUY ADD 7988 79
printorderbook 25
SELL ADD 7803 429
printorderbook 48
BUY ADD 7837 174
printorderbook 11
SELL ADD 7916 14
printorderbook 54
SELL ADD 7984 216
printorderbook 58
BUY ADD 7903 82
BUY CANCEL 49 314
printorderbook 38
BUY ADD 7909 334
printorderbook 40
SELL ADD 7899 17
printorderbook 37
SELL ADD 7820 276
printorderbook 43
BUY ADD 7896 349
printorderbook 35
BUY ADD 7854 141
printorderbook 38
SELL ADD 7918 460
printorderbook 58
SELL ADD 7979 326
BUY CANCEL 85 334
printorderbook 60
BUY ADD 7824 352
printorderbook 8
SELL ADD 7868 379
printorderbook 24
BUY ADD 7839 487
printorderbook 35
BUY ADD 7831 75
printorderbook 27
SELL ADD 7929 31
printorderbook 63
BUY ADD 7833 17
printorderbook 37
SELL ADD 7916 406
BUY CANCEL 92 352
printorderbook 41
BUY ADD 7837 360
printorderbook 6
BUY ADD 7817 209
printorderbook 48
BUY ADD 7953 448
printorderbook 35
SELL ADD 7937 39
printorderbook 34
SELL ADD 7994 341
printorderbook 26
BUY ADD 7814 242
printorderbook 35
BUY ADD 7828 41
SELL CANCEL 43 303
printorderbook 67
SELL ADD 7838 288
printorderbook 41
SELL ADD 7919 75
printorderbook 70
SELL ADD 7963 188
printorderbook 34
BUY ADD 7959 179
printorderbook 24
SELL ADD 7932 158
printorderbook 43
BUY ADD 7902 133
printorderbook 59
BUY ADD 7891 79
SELL CANCEL 75 117
printorderbook 56
SELL ADD 7863 360
printorderbook 17
SELL ADD 7814 284
printorderbook 30
SELL ADD 7871 295
printorderbook 33
BUY ADD 7809 298
printorderbook 61
SELL ADD 7966 330
printorderbook 2
SELL ADD 7904 360
printorderbook 59
BUY ADD 7928 268
BUY CANCEL 39 430
printorderbook 32
SELL ADD 7822 418
printorderbook 24
BUY ADD 7985 122
printorderbook 42
SELL ADD 7838 418
printorderbook 44
BUY ADD 7973 59
printorderbook 48
SELL ADD 7805 428
printorderbook 47
SELL ADD 7855 89
printorderbook 63
BUY ADD 7937 285
SELL CANCEL 55 64
printorderbook 15
SELL ADD 7848 239
printorderbook 67
SELL ADD 7955 480
printorderbook 41
SELL ADD 7899 253
printorderbook 9
BUY ADD 7876 416
printorderbook 10
BUY ADD 7969 54
printorderbook 26
BUY ADD 7915 79
printorderbook 13
BUY ADD 7976 172
SELL CANCEL 93 379
printorderbook 56
SELL ADD 7833 38
printorderbook 53
SELL ADD 7954 218
printorderbook 65
SELL ADD 7958 108
printorderbook 27
BUY ADD 7922 179
printorderbook 15
BUY ADD 7803 58
printorderbook 46
SELL ADD 7865 457
printorderbook 28
BUY ADD 7825 471
SELL CANCEL 50 53
printorderbook 40
BUY ADD 7962 218
printorderbook 25
BUY ADD 7948 388
printorderbook 43
SELL ADD 7824 68
printorderbook 10
BUY ADD 7891 118
printorderbook 48
BUY ADD 7823 472
printorderbook 5
SELL ADD 7844 300
printorderbook 5
BUY ADD 7805 487
BUY CANCEL 99 360
printorderbook 17
BUY ADD 7845 224
printorderbook 65
BUY ADD 7971 305
printorderbook 44
BUY ADD 7804 105
printorderbook 40
SELL ADD 7827 272
printorderbook 62
SELL ADD 7859 457
printorderbook 68
BUY ADD 7889 347
printorderbook 33
SELL ADD 7892 259
SELL CANCEL 139 457
printorderbook 10
BUY ADD 7881 17
printorderbook 14
SELL ADD 7881 361
printorderbook 45
SELL ADD 7868 247
printorderbook 23
SELL ADD 7876 29
printorderbook 54
BUY ADD 7999 176
printorderbook 15
BUY ADD 7839 257
printorderbook 43
BUY ADD 7828 262
BUY CANCEL 92 352
printorderbook 48
BUY ADD 7865 372
printorderbook 29
BUY ADD 7922 307
printorderbook 4
SELL ADD 7833 212
printorderbook 51
SELL ADD 7816 210
printorderbook 23
BUY ADD 7905 31
printorderbook 9
BUY ADD 7824 31
printorderbook 64
BUY ADD 7909 423
BUY CANCEL 112 79
printorderbook 68
SELL ADD 7856 299
printorderbook 5
BUY ADD 7855 216
printorderbook 15
BUY ADD 7934 342
printorderbook 13
BUY ADD 7800 90
printorderbook 47
BUY ADD 7892 48
printorderbook 32
BUY ADD 7975 103
printorderbook 2
SELL ADD 7911 124
BUY CANCEL 6 37
printorderbook 62
BUY ADD 7896 468
printorderbook 39
BUY ADD 7833 191
printorderbook 68
SELL ADD 7977 126
printorderbook 59
BUY ADD 7904 47
printorderbook 55
SELL ADD 7950 323
printorderbook 12
SELL ADD 7831 205
printorderbook 13
BUY ADD 7866 178
BUY CANCEL 59 385
printorderbook 45
SELL ADD 7815 246
printorderbook 18
BUY ADD 7799 51
printorderbook 67
SELL ADD 7822 481
printorderbook 16
SELL ADD 7848 275
printorderbook 60
BUY ADD 7979 380
printorderbook 70
SELL ADD 7948 383
printorderbook 45
SELL ADD 7972 466
BUY CANCEL 56 213
printorderbook 68
BUY ADD 7837 383
printorderbook 3
SELL ADD 7838 299
printorderbook 39
BUY ADD 7941 442
printorderbook 70
SELL ADD 7949 345
printorderbook 13
SELL ADD 7981 200
printorderbook 63
BUY ADD 7852 119
printorderbook 24
SELL ADD 7932 410
SELL CANCEL 107 75
printorderbook 52
BUY ADD 7880 351
printorderbook 47
SELL ADD 7859 477
printorderbook 63
BUY ADD 7881 398
printorderbook 43
SELL ADD 7814 192
printorderbook 28
BUY ADD 7939 7
printorderbook 28
BUY ADD 7853 82
printorderbook 57
SELL ADD 7929 37
SELL CANCEL 78 466
printorderbook 35
SELL ADD 7870 446
printorderbook 31
BUY ADD 7914 72
printorderbook 35
SELL ADD 7834 188
printorderbook 12
SELL ADD 7957 126
printorderbook 39
BUY ADD 7869 207
printorderbook 64
BUY ADD 7879 403
printorderbook 4
SELL ADD 7993 104
SELL CANCEL 175 124
printorderbook 22
BUY ADD 7866 42
printorderbook 48
SELL ADD 7832 100
printorderbook 61
